Workbook

Sheet Dep Calculation
J1: Dep Calculation
B2: 2021 | C2: 2022 | D2: 2023 | E2: 2024 | F2: 2025 | G2: 2026 | I2: 2021 | J2: 2022 | K2: 2023 | L2: 2024 | M2: 2025 | N2: 2026
A3: Adj. Company-Operated Restaurants - Occupancy & other op. expenses | B3: =Raw!C56 -> 2273.3 | I3: =B3/SUM($B$3:$B$4)*$B$8 -> 921.54411
A4: Adj. Franchised Restaurants Occupancy Expenses | B4: =Raw!C57 -> 2335 | I4: =B4/SUM($B$3:$B$4)*$B$8 -> 946.55589
A8: Total Dep | B8: =Raw!C76 -> 1868.1 | C8: =Raw!D76 -> 1870.6
A9: dep | B9: =Raw!C77 -> 1530.7 | C9: =Raw!D77 -> 1454

Sheet Raw
A2: Information | C2: 12 months | D2: 12 months | E2: 12 months | F2: 12 months | G2: 12 months | H2: 3 | I2: 3
C3: Dec. 31, 2021 | D3: Dec. 31, 2022 | E3: Dec. 31, 2023 | F3: Dec. 31, 2024 | G3: Dec. 31, 2025 | H3: 46112 | I3: 45747
A4: SEGMENT REVENUE
A5: Segmental Net Operating Revenue (GAAP - Reported)
A6: Company-operated sales: | C6: 9787 | D6: 8748 | E6: 9742 | F6: 15715 | G6: 16548 | H6: 2317 | I6: 2132
A7: Franchised revenues: | C7: 13085 | D7: 14106 | E7: 15436 | F7: 9782 | G7: 9690 | H7: 4007 | I7: 3661
A8: Total Other revenues | C8: 350 | D8: 329 | E8: 316 | F8: 423 | G8: 647 | H8: 193 | I8: 162
A9: Total Revenues | C9: =SUM(C6:C8) -> 23222 | D9: =SUM(D6:D8) -> 23183 | E9: =SUM(E6:E8) -> 25494 | F9: =SUM(F6:F8) -> 25920 | G9: =SUM(G6:G8) -> 26885 | H9: =SUM(H6:H8) -> 6517 | I9: =SUM(I6:I8) -> 5955
A10: Source | C10: 2021 10K, Page 13 | D10: 2022 10K, Page 13 | E10: 2023 10K, Page 14 | F10: 2024 10K, Page 14 | G10: 2025 10K, Page 14 | H10: 2026 10Q Q1, Page 4 | I10: 2026 10Q Q1, Page 11
A12: % Change Organic Revenues (non-GAAP) | H12: 3m-o-3m
A13: Company-operated sales: | C13: 18 % | D13: 4 % | E13: 0.12 | F13: 0.02 | G13: 0.04 | H13: 0.03
A14: Franchised revenues: | C14: 19 % | D14: 14 % | E14: 0.09 | F14: 0.01 | G14: 0.02 | H14: 0.05
A15: Total Company-operated sales and Franchised revenues: | C15: 19 % | D15: 0.06 | E15: 0.1 | F15: 0.01 | G15: 0.01 | H15: 0.04
A16: Total Other revenues | C16: — % | D16: 0.03 | E16: 0.03 | F16: 0.34 | G16: 0.52 | H16: 0.16
A17: Total Revenues | C17: 18 % | D17: 0.06 | E17: 0.1 | F17: 0.02 | G17: 0.02 | H17: 0.04
C18: 2021 10K, Page 13 | D18: 2022 10K, Page 13 | E18: 2023 10K, Page 14 | F18: 2024 10K, Page 14 | G18: 2025 10K, Page 14 | H18: 2026 8K, Page 11
A21: INCOME STATEMENT ITEMS
A22: Reported Numbers from Inc. Statement (GAAP)
A23: Sales by Company Operated Restaurants | C23: 9787.4 | D23: 8748.4 | E23: 9741.6 | F23: 9782 | G23: 9690 | H23: 2317
A24: Revenues from franchised operations | C24: 13085.4 | D24: 14105.8 | E24: 15436.5 | F24: 15715 | G24: 16548 | H24: 4007
A25: Other Revenues | C25: 350.1 | D25: 328.4 | E25: 315.6 | F25: 423 | G25: 647 | H25: 193
A26: Net Operating Revenue | C26: =C23+C24+C25 -> 23222.9 | D26: =D23+D24+D25 -> 23182.6 | E26: =E23+E24+E25 -> 25493.7 | F26: =F23+F24+F25 -> 25920 | G26: =G23+G24+G25 -> 26885 | H26: =H23+H24+H25 -> 6517
A27: Company-Operated Restaurants - Food & Paper | C27: 3096.8 | D27: 2737.3 | E27: 3039 | F27: 2995 | G27: 3006 | H27: 0
A28: Company-Operated Restaurants - Payroll | C28: 2677.2 | D28: 2617.4 | E28: 2885.8 | F28: 2959 | G28: 2905 | H28: 0
A29: Company-Operated Restaurants - Occupancy & other op. expenses | C29: 2273.3 | D29: 2026.2 | E29: 2299.3 | F29: 2381 | G29: 2358 | H29: 2032
A30: Franchised Restaurants Occupancy Expenses | C30: 2335 | D30: 2349.7 | E30: 2474.6 | F30: 2536 | G30: 2618 | H30: 676
A31: Other Restaurant Expenses | C31: 260.4 | D31: 244.8 | E31: 232.5 | F31: 339 | G31: 564 | H31: 166
A32: Selling, general & administrative expenses
A33: Depreciation & Amortization | C33: 329.7 | D33: 370.4 | E33: 381.7 | F33: 447 | G33: 457 | H33: 111
A34: Other | C34: 2377.8 | D34: 2492.2 | E34: 2435.2 | F34: 2412 | G34: 2583 | H34: 648
A35: Other Operating (Income) Expense, Net | C35: -483.3 | D35: 973.6 | E35: 98.9 | F35: 139 | G35: 2 | H35: -69
A36: OPERATING INCOME | C36: =C26-SUM(C27:C35) -> 10356 | D36: =D26-SUM(D27:D35) -> 9371 | E36: =E26-SUM(E27:E35) -> 11646.7 | F36: =F26-SUM(F27:F35) -> 11712 | G36: =G26-SUM(G27:G35) -> 12392 | H36: =H26-SUM(H27:H35) -> 2953
A37: Interest Expense--net of capitalized interest | C37: 1185.8 | D37: 1207 | E37: 1360.8 | F37: 1506 | G37: 1582 | H37: 400
A38: Nonoperating (Income) expense, net | C38: 42.3 | D38: 338.6 | E38: -236.3 | F38: -139 | G38: -87 | H38: 11
A39: INCOME BEFORE INCOME TAXES | C39: =C36-C37-C38 -> 9127.9 | D39: =D36-D37-D38 -> 7825.4 | E39: =E36-E37-E38 -> 10522.2 | F39: =F36-F37-F38 -> 10345 | G39: =G36-G37-G38 -> 10897 | H39: =H36-H37-H38 -> 2542
A40: Tax | C40: 1582.7 | D40: 1648 | E40: 2053.4 | F40: 2121 | G40: 2334 | H40: 559
A41: CONSOL. NET INCOME | C41: =C39-C40 -> 7545.2 | D41: =D39-D40 -> 6177.4 | E41: =E39-E40 -> 8468.8 | F41: =F39-F40 -> 8224 | G41: =G39-G40 -> 8563 | H41: =H39-H40 -> 1983
A42: Profit Attributable to NCI (from Inc. St.) | C42: 0 | D42: 0 | E42: 0 | F42: 0 | G42: 0 | H42: 0
A43: NET INCOME ATTRIBUTABLE TO SH. HOLDERS | C43: =C41-C42 -> 7545.2 | D43: =D41-D42 -> 6177.4 | E43: =E41-E42 -> 8468.8 | F43: =F41-F42 -> 8224 | G43: =G41-G42 -> 8563 | H43: =H41-H42 -> 1983
A44: Basic Number of Shares | C44: 746.3 | D44: 736.5 | E44: 727.9 | F44: 718.3 | G44: 713.4 | H44: 710.7
...

Sheet Revenue Segments
A1: McDONALD’S CORPORATION
A2: (in USD millions) | C2: Valuation Date
A3: Segment Information | C3: 12 months | D3: 12 months | E3: 12 months | F3: 12 months | G3: 12 months | I3: 3 | J3: 3 | L3: 9 | M3: 9 | O3: 12 months | P3: 12 months | Q3: 12 months | R3: 12 months | S3: 12 months | T3: 12 months
C4: Dec. 31, 2021 | D4: Dec. 31, 2022 | E4: Dec. 31, 2023 | F4: Dec. 31, 2024 | G4: Dec. 31, 2025 | I4: 45747 | J4: 46112 | L4: Dec. 31, 2025 | M4: Dec. 31, 2026 | O4: Dec. 31, 2026 | P4: Dec. 31, 2027 | Q4: Dec. 31, 2028 | R4: Dec. 31, 2029 | S4: Dec. 31, 2030 | T4: Dec. 31, 2031
A6: Company-operated sales: | C6: =Raw!C6 -> 9787 | D6: =Raw!D6 -> 8748 | E6: =Raw!E6 -> 9742 | F6: =Raw!F6 -> 15715 | G6: =Raw!G6 -> 16548 | I6: =Raw!I6 -> 2132 | J6: =Raw!H6 -> 2317 | L6: =G6-I6 -> 14416 | M6: =L6*(1+J8) -> 14848.48 | O6: =J6+M6 -> 17165.48 | P6: =O6*(1+$O8) -> 17937.927 | Q6: =P6*(1+$O8) -> 18745.133 | R6: =Q6*(1+$O8) -> 19588.664 | S6: =R6*(1+$O8) -> 20470.154 | T6: =S6*(1+$O8) -> 21391.311
A7: Reported Y-o-Y Growth % (GAAP)
A8: Organic Growth % (non-GAAP) | C8: =Raw!C13 -> 18 % | D8: =Raw!D13 -> 4 % | E8: =Raw!E13 -> 0.12 | F8: =Raw!F13 -> 0.02 | G8: =Raw!G13 -> 0.04 | H8: =AVERAGE(C8:G8) -> 0.06 | J8: =Raw!H13 -> 0.03 | O8: =AVERAGE(H8,J8) -> 0.045
A10: Franchised revenues: | C10: =Raw!C7 -> 13085 | D10: =Raw!D7 -> 14106 | E10: =Raw!E7 -> 15436 | F10: =Raw!F7 -> 9782 | G10: =Raw!G7 -> 9690 | I10: =Raw!I7 -> 3661 | J10: =Raw!H7 -> 4007 | L10: =G10-I10 -> 6029 | M10: =L10*(1+J12) -> 6330.45 | O10: =J10+M10 -> 10337.45 | P10: =O10*(1+$O12) -> 10802.635 | Q10: =P10*(1+$O12) -> 11288.754 | R10: =Q10*(1+$O12) -> 11796.748 | S10: =R10*(1+$O12) -> 12327.601 | T10: =S10*(1+$O12) -> 12882.343
A11: Reported Y-o-Y Growth % (GAAP)
A12: Organic Growth % (non-GAAP) | C12: =Raw!C14 -> 19 % | D12: =Raw!D14 -> 14 % | E12: =Raw!E14 -> 0.09 | F12: =Raw!F14 -> 0.01 | G12: =Raw!G14 -> 0.02 | H12: =AVERAGE(C12:G12) -> 0.04 | J12: =Raw!H14 -> 0.05 | O12: =AVERAGE(H12,J12) -> 0.045
A14: Total Other revenues: | C14: =Raw!C8 -> 350 | D14: =Raw!D8 -> 329 | E14: =Raw!E8 -> 316 | F14: =Raw!F8 -> 423 | G14: =Raw!G8 -> 647 | I14: =Raw!I8 -> 162 | J14: =Raw!H8 -> 193 | L14: =G14-I14 -> 485 | M14: =L14*(1+J16) -> 562.6 | O14: =J14+M14 -> 755.6 | P14: =O14*(1+$O16) -> 902.942 | Q14: =P14*(1+$O16) -> 1079.0157 | R14: =Q14*(1+$O16) -> 1289.4237 | S14: =R14*(1+$O16) -> 1540.8614 | T14: =S14*(1+$O16) -> 1841.3293
A15: Reported Y-o-Y Growth % (GAAP)
A16: Organic Growth % (non-GAAP) | C16: =Raw!C16 -> — % | D16: =Raw!D16 -> 0.03 | E16: =Raw!E16 -> 0.03 | F16: =Raw!F16 -> 0.34 | G16: =Raw!G16 -> 0.52 | H16: =AVERAGE(C16:G16) -> 0.23 | J16: =Raw!H16 -> 0.16 | O16: =AVERAGE(H16,J16) -> 0.195
A18: Total Division | C18: =SUM(C6,C10,C14) -> 23222 | D18: =SUM(D6,D10,D14) -> 23183 | E18: =SUM(E6,E10,E14) -> 25494 | F18: =SUM(F6,F10,F14) -> 25920 | G18: =SUM(G6,G10,G14) -> 26885 | I18: =SUM(I6,I10,I14) -> 5955 | J18: =SUM(J6,J10,J14) -> 6517 | L18: =SUM(L6,L10,L14) -> 20930 | M18: =SUM(M6,M10,M14) -> 21741.53 | O18: =SUM(O6,O10,O14) -> 28258.53 | P18: =SUM(P6,P10,P14) -> 29643.504 | Q18: =SUM(Q6,Q10,Q14) -> 31112.903 | R18: =SUM(R6,R10,R14) -> 32674.836 | S18: =SUM(S6,S10,S14) -> 34338.617 | T18: =SUM(T6,T10,T14) -> 36114.984
A21: ALTERNATIVE METHOD
A23: Management guidance | C23: 0.06
A25: Total Division | G25: =G18 -> 26885 | J25: =J18 -> 6517 | M25: =G25*(1+C23)-J25 -> 21981.1 | O25: =J25+M25 -> 28498.1 | P25: =O25*(1+$C$23) -> 30207.986 | Q25: =P25*(1+$C$23) -> 32020.465 | R25: =Q25*(1+$C$23) -> 33941.693 | S25: =R25*(1+$C$23) -> 35978.195 | T25: =S25*(1+$C$23) -> 38136.886
A27: 6.0% growth assumed based on management-reported 6% constant-currency Systemwide sales growth and expected restaurant expansion contribution of 2.5% in FY2026.Refer FORM 8-K (page 16), Date of report: May 7, 2026.

Sheet McD IS
A1: McDONALD’S CORPORATION | G1: HISTORICAL STUB | H1: FORECAST STUB
A2: (in USD million except per Share Data)
A3: Income Statement | B3: 12 | C3: 12 | D3: 12 | E3: 12 | F3: 12 | G3: 3 | H3: 9 | I3: 12 | J3: 12 | K3: 12 | L3: 12 | M3: 12 | N3: 12
B4: 44561 | C4: 44926 | D4: 45291 | E4: 45657 | F4: 46022 | G4: 46112 | H4: 46387 | I4: 46387 | J4: 46752 | K4: 47118 | L4: 47483 | M4: 47848 | N4: 48213
A6: Net Operating Revenues - Reported | B6: =Raw!C26 -> 23222.9 | C6: =Raw!D26 -> 23182.6 | D6: =Raw!E26 -> 25493.7 | E6: =Raw!F26 -> 25920 | F6: =Raw!G26 -> 26885 | G6: =Raw!H26 -> 6517
A7: Other Items (affecting Comparability) | B7: =B8-B6 -> 0 | C7: =C8-C6 -> 0 | D7: =D8-D6 -> 0 | E7: =E8-E6 -> 0 | F7: =F8-F6 -> 0 | G7: =G8-G6 -> 0
A8: Net Operating Revenues - Normalised/Adjusted | B8: =Raw!C53 -> 23222.9 | C8: =Raw!D53 -> 23182.6 | D8: =Raw!E53 -> 25493.7 | E8: =Raw!F53 -> 25920 | F8: =Raw!G53 -> 26885 | G8: =Raw!H53 -> 6517 | H8: ='Revenue Segments'!M25 -> 21981.1 | I8: =H8+G6 -> 28498.1 | J8: ='Revenue Segments'!P25 -> 30207.986 | K8: ='Revenue Segments'!Q25 -> 32020.465 | L8: ='Revenue Segments'!R25 -> 33941.693 | M8: ='Revenue Segments'!S25 -> 35978.195 | N8: ='Revenue Segments'!T25 -> 38136.886
A10: Cost of Goods and Services Sold - Reported | B10: =SUM(Raw!C27:C31) -> 10642.7 | C10: =SUM(Raw!D27:D31) -> 9975.4 | D10: =SUM(Raw!E27:E31) -> 10931.2 | E10: =SUM(Raw!F27:F31) -> 11210 | F10: =SUM(Raw!G27:G31) -> 11451 | G10: =SUM(Raw!H27:H31) -> 2874
A11: Impact of Special Items
A12: Cost of Goods and Services Sold - Normalised/Adjusted | B12: =SUM(Raw!C27:C31) -> 10642.7 | C12: =SUM(Raw!D27:D31) -> 9975.4 | D12: =SUM(Raw!E27:E31) -> 10931.2 | E12: =SUM(Raw!F27:F31) -> 11210 | F12: =SUM(Raw!G27:G31) -> 11451 | G12: =SUM(Raw!H27:H31) -> 2874
A13: Depreciation & Amort. (PPE) | B13: =Raw!C77 -> 1530.7 | C13: =Raw!D77 -> 1454 | D13: =Raw!E77 -> 1501 | E13: =Raw!F77 -> 1500 | F13: =Raw!G77 -> 1600 | G13: =Raw!H77 -> 429.97447
A14: Cost of Goods and Services Sold - Normalized (after removing Dep.) | B14: =B12-B13 -> 9112 | C14: =C12-C13 -> 8521.4 | D14: =D12-D13 -> 9430.2 | E14: =E12-E13 -> 9710 | F14: =F12-F13 -> 9851 | G14: =G12-G13 -> 2444.0255 | H14: =H8*H79 -> 8227.8982 | I14: =H14+G14 -> 10671.924 | J14: =J8*$H$79 -> 11307.361 | K14: =K8*$H$79 -> 11985.803 | L14: =L8*$H$79 -> 12704.951 | M14: =M8*$H$79 -> 13467.248 | N14: =N8*$H$79 -> 14275.283
A16: Gross Profit - Reported | B16: =B6-B10 -> 12580.2 | C16: =C6-C10 -> 13207.2 | D16: =D6-D10 -> 14562.5 | E16: =E6-E10 -> 14710 | F16: =F6-F10 -> 15434 | G16: =G6-G10 -> 3643
A17: Gross Profit - Normalised/Adjusted | B17: =B8-B14 -> 14110.9 | C17: =C8-C14 -> 14661.2 | D17: =D8-D14 -> 16063.5 | E17: =E8-E14 -> 16210 | F17: =F8-F14 -> 17034 | G17: =G8-G14 -> 4072.9745 | H17: =H8-H14 -> 13753.202 | I17: =H17+G17 -> 17826.176 | J17: =J8-J14 -> 18900.625 | K17: =K8-K14 -> 20034.662 | L17: =L8-L14 -> 21236.742 | M17: =M8-M14 -> 22510.947 | N17: =N8-N14 -> 23861.604
A19: Selling, General and Administrative Expense - Reported | B19: =Raw!C34+B20 -> 2385.5 | C19: =Raw!D34+C20 -> 2538.4 | D19: =Raw!E34+D20 -> 2530.7 | E19: =Raw!F34+E20 -> 2562 | F19: =Raw!G34+F20 -> 2725 | G19: =Raw!H34+G20 -> 672.13442
A20: Impact of Special Items | B20: =Raw!C81 -> 7.7 | C20: =Raw!D81 -> 46.2 | D20: =Raw!E81 -> 95.5 | E20: =Raw!F81 -> 150 | F20: =Raw!G81 -> 142 | G20: =Raw!H81 -> 24.134418
A21: Selling, General and Administrative Expense - Normalised/Adjusted | B21: =B19-B20 -> 2377.8 | C21: =C19-C20 -> 2492.2 | D21: =D19-D20 -> 2435.2 | E21: =E19-E20 -> 2412 | F21: =F19-F20 -> 2583 | G21: =G19-G20 -> 648 | H21: =H8*H81 -> 2176.0508 | I21: =H21+G21 -> 2824.0508 | J21: =J8*$H$81 -> 2990.4833 | K21: =K8*$H$81 -> 3169.9123 | L21: =L8*$H$81 -> 3360.107 | M21: =M8*$H$81 -> 3561.7134 | N21: =N8*$H$81 -> 3775.4162
A23: Other Cost and Expense, Operating - Reported | B23: =Raw!C35 -> -483.3 | C23: =Raw!D35 -> 973.6 | D23: =Raw!E35 -> 98.9 | E23: =Raw!F35 -> 139 | F23: =Raw!G35 -> 2 | G23: =Raw!H35 -> -69
A24: Impact of Special Items | B24: =B25-B23 -> -285 | C24: =C25-C23 -> 1010 | D24: =D25-D23 -> 290 | E24: =E25-E23 -> 291 | F24: =F25-F23 -> 229 | G24: =G25-G23 -> 47
A25: Other Cost and Expense, Operating - Normalised/Adjusted | B25: =Raw!C61 -> -768.3 | C25: =Raw!D61 -> 1983.6 | D25: =Raw!E61 -> 388.9 | E25: =Raw!F61 -> 430 | F25: =Raw!G61 -> 231 | G25: =Raw!H61 -> -22 | H25: =H8*H83 -> 328.0352 | I25: =H25+G25 -> 306.0352 | J25: =J8*$H$83 -> 450.80923 | K25: =K8*$H$83 -> 477.85779 | L25: =L8*$H$83 -> 506.52926 | M25: =M8*$H$83 -> 536.92101 | N25: =N8*$H$83 -> 569.13627
A27: EBITDA - Normalized/Adjusted | B27: =B17-B21-B25 -> 12501.4 | C27: =C17-C21-C25 -> 10185.4 | D27: =D17-D21-D25 -> 13239.4 | E27: =E17-E21-E25 -> 13368 | F27: =F17-F21-F25 -> 14220 | G27: =G17-G21-G25 -> 3446.9745 | H27: =H17-H21-H25 -> 11249.116 | I27: =H27+G294 -> 11249.116 | J27: =J17-J21-J25 -> 15459.332 | K27: =K17-K21-K25 -> 16386.892 | L27: =L17-L21-L25 -> 17370.106 | M27: =M17-M21-M25 -> 18412.312 | N27: =N17-N21-N25 -> 19517.051
A29: Total Depreciation & Amortization Expense (Reported) | B29: =Raw!C76 -> 1868.1 | C29: =Raw!D76 -> 1870.6 | D29: =Raw!E76 -> 1978.2 | E29: =Raw!F76 -> 2097 | F29: =Raw!G76 -> 2199 | G29: =Raw!H76 -> 566
A30: Impact of Special Items | B30: =Raw!C81 -> 7.7 | C30: =Raw!D81 -> 46.2 | D30: =Raw!E81 -> 95.5 | E30: =Raw!F81 -> 150 | F30: =Raw!G81 -> 142 | G30: =Raw!H81 -> 24.134418
A31: Total Depreciation & Amortization Expense (Normalized) | B31: =B29-B30 -> 1860.4 | C31: =C29-C30 -> 1824.4 | D31: =D29-D30 -> 1882.7 | E31: =E29-E30 -> 1947 | F31: =F29-F30 -> 2057 | G31: =G29-G30 -> 541.86558 | H31: ='Fixed Assets Schedule'!H9 -> 1611.7207 | I31: =H31+G31 -> 2153.5863 | J31: ='Fixed Assets Schedule'!I9 -> 2264.9842 | K31: ='Fixed Assets Schedule'!J9 -> 2348.9096 | L31: ='Fixed Assets Schedule'!K9 -> 2441.518 | M31: ='Fixed Assets Schedule'!L9 -> 2543.0744 | N31: ='Fixed Assets Schedule'!M9 -> 2653.8777
A33: Operating Income (EBIT) - Reported | B33: =B16-B19-B23 -> 10678 | C33: =C16-C19-C23 -> 9695.2 | D33: =D16-D19-D23 -> 11932.9 | E33: =E16-E19-E23 -> 12009 | F33: =F16-F19-F23 -> 12707 | G33: =G16-G19-G23 -> 3039.8656
A34: Operating Income (EBIT) - Normalised/Adjusted | B34: =B27-B31 -> 10641 | C34: =C27-C31 -> 8361 | D34: =D27-D31 -> 11356.7 | E34: =E27-E31 -> 11421 | F34: =F27-F31 -> 12163 | G34: =G27-G31 -> 2905.1089 | H34: =H27-H29 -> 11249.116 | I34: =H34+G34 -> 14154.225 | J34: =J27-J29 -> 15459.332 | K34: =K27-K29 -> 16386.892 | L34: =L27-L29 -> 17370.106 | M34: =M27-M29 -> 18412.312 | N34: =N27-N29 -> 19517.051
A36: Interest Expense-Reported | B36: =Raw!C37 -> 1185.8 | C36: =Raw!D37 -> 1207 | D36: =Raw!E37 -> 1360.8 | E36: =Raw!F37 -> 1506 | F36: =Raw!G37 -> 1582 | G36: =Raw!H37 -> 400
A37: Impact of Special Items
A38: Interest expense - Normalised/Adjusted | B38: =Raw!C63 -> 1185.8 | C38: =Raw!D63 -> 1207 | D38: =Raw!E63 -> 1360.8 | E38: =Raw!F63 -> 1506 | F38: =Raw!G63 -> 1582 | G38: =Raw!H63 -> 400 | H38: ='Debt Schedule'!H13 -> 1152.9111 | I38: =H38+G38 -> 1552.9111 | J38: ='Debt Schedule'!I13 -> 1475.868 | K38: ='Debt Schedule'!J13 -> 1315.5155 | L38: ='Debt Schedule'!K13 -> 1146.8071 | M38: ='Debt Schedule'!L13 -> 1019.399 | N38: ='Debt Schedule'!M13 -> 961.69354
A40: Nonoperating (Income) expense, net - Reported | B40: =Raw!C38 -> 42.3 | C40: =Raw!D38 -> 338.6 | D40: =Raw!E38 -> -236.3 | E40: =Raw!F38 -> -139 | F40: =Raw!G38 -> -87 | G40: =Raw!H38 -> 11
A41: Impact of Special Items
A42: Other income (loss) - net Normalised/Adjusted | B42: =Raw!C64 -> 42.3 | C42: =Raw!D64 -> 338.6 | D42: =Raw!E64 -> -236.3 | E42: =Raw!F64 -> -139 | F42: =Raw!G64 -> -87 | G42: =Raw!H64 -> 11 | H42: =H8*H85 -> 0.90685552 | I42: =H42+G42 -> 11.906856 | J42: =J8*$H$85 -> 1.2462652 | K42: =K8*$H$85 -> 1.3210411 | L42: =L8*$H$85 -> 1.4003035 | M42: =M8*$H$85 -> 1.4843217 | N42: =N8*$H$85 -> 1.573381
A44: EBT- Reported | B44: =B33-B36-B40 -> 9449.9 | C44: =C33-C36+C40 -> 8826.8 | D44: =D33-D36+D40 -> 10335.8 | E44: =E33-E36+E40 -> 10364 | F44: =F33-F36+F40 -> 11038 | G44: =G33-G36+G40 -> 2650.8656
A45: EBT- Normalised/Adjusted | B45: =B34-B38-B42 -> 9412.9 | C45: =C34-C38-C42 -> 6815.4 | D45: =D34-D38-D42 -> 10232.2 | E45: =E34-E38-E42 -> 10054 | F45: =F34-F38-F42 -> 10668 | G45: =G34-G38-G42 -> 2494.1089 | H45: =H34-H38+H42 -> 10097.112 | I45: =H45+G45 -> 12591.22 | J45: =J34-J38+J42 -> 13984.711 | K45: =K34-K38+K42 -> 15072.698 | L45: =L34-L38+L42 -> 16224.699 | M45: =M34-M38+M42 -> 17394.398 | N45: =N34-N38+N42 -> 18556.931
A47: Income Tax Expense-Reported | B47: =Raw!C40 -> 1582.7 | C47: =Raw!D40 -> 1648 | D47: =Raw!E40 -> 2053.4 | E47: =Raw!F40 -> 2121 | F47: =Raw!G40 -> 2334 | G47: =Raw!H40 -> 559
A48: Impact of Special Items | B48: =B49-B47 -> 364 | C48: =C49-C47 -> -537 | D48: =D49-D47 -> 0 | E48: =E49-E47 -> 0 | F48: =F49-F47 -> 0 | G48: =G49-G47 -> 0
A49: Income Tax Expense-Normalised/Adjusted | B49: =Raw!C66 -> 1946.7 | C49: =Raw!D66 -> 1111 | D49: =Raw!E66 -> 2053.4 | E49: =Raw!F66 -> 2121 | F49: =Raw!G66 -> 2334 | G49: =Raw!H66 -> 559 | H49: =H45*H89 -> 2060.4493 | I49: =H49+G49 -> 2619.4493 | J49: =J45*$H$89 -> 2853.7653 | K49: =K45*$H$89 -> 3075.7835 | L49: =L45*$H$89 -> 3310.8646 | M49: =M45*$H$89 -> 3549.5571 | N49: =N45*$H$89 -> 3786.7874
A51: Net Income-Reported | B51: =B44-B47 -> 7867.2 | C51: =C44-C47 -> 7178.8 | D51: =D44-D47 -> 8282.4 | E51: =E44-E47 -> 8243 | F51: =F44-F47 -> 8704 | G51: =G44-G47 -> 2091.8656
A52: Net Income-Normalised | B52: =B45-B49 -> 7466.2 | C52: =C45-C49 -> 5704.4 | D52: =D45-D49 -> 8178.8 | E52: =E45-E49 -> 7933 | F52: =F45-F49 -> 8334 | G52: =G45-G49 -> 1935.1089 | H52: =H45-H49 -> 8036.6623 | I52: =H52+G52 -> 9971.7712 | J52: =J45-J49 -> 11130.945 | K52: =K45-K49 -> 11996.914 | L52: =L45-L49 -> 12913.835 | M52: =M45-M49 -> 13844.841 | N52: =N45-N49 -> 14770.143
A54: Share of noncontrolling interests-Reported | B54: 0 | C54: 0 | D54: 0 | E54: 0 | F54: 0 | G54: 0
...

Sheet McD-BS
A1: McDONALD’S CORPORATION
A2: (in USD million except per Share Data)
A3: Balance Sheet | B3: 12 | C3: 12 | D3: 12 | E3: 12 | F3: 12 | G3: 3 | H3: 9 | I3: 12 | J3: 12 | K3: 12 | L3: 12 | M3: 12
B4: 44561 | C4: 44926 | D4: 45291 | E4: 45657 | F4: 46022 | G4: 46112 | H4: 46387 | I4: 46752 | J4: 47118 | K4: 47483 | L4: 47848 | M4: 48213
A6: Current Assets
A7: Cash and cash equivalents | B7: =Raw!C91 -> 4709.2 | C7: =Raw!D91 -> 2583.8 | D7: =Raw!E91 -> 4579.3 | E7: =Raw!F91 -> 1085 | F7: =Raw!G91 -> 774 | G7: =Raw!H91 -> 1170 | H7: ='McD-CFS'!H28 -> 3645.6943 | I7: ='McD-CFS'!I28 -> 3738.8673 | J7: ='McD-CFS'!J28 -> 2088.4862 | K7: ='McD-CFS'!K28 -> 2204.5804 | L7: ='McD-CFS'!L28 -> 3186.2444 | M7: ='McD-CFS'!M28 -> 7412.6227
A8: Total Cash, Cash equivalents & Short term investments | B8: =Raw!C92 -> 4709.2 | C8: =Raw!D92 -> 2583.8 | D8: =Raw!E92 -> 4579.3 | E8: =Raw!F92 -> 1085 | F8: =Raw!G92 -> 774 | G8: =Raw!H92 -> 1170 | H8: =H7 -> 3645.6943 | I8: =I7 -> 3738.8673 | J8: =J7 -> 2088.4862 | K8: =K7 -> 2204.5804 | L8: =L7 -> 3186.2444 | M8: =M7 -> 7412.6227
A9: Accounts and notes receivable | B9: =Raw!C93 -> 1872.4 | C9: =Raw!D93 -> 2115 | D9: =Raw!E93 -> 2488 | E9: =Raw!F93 -> 2383 | F9: =Raw!G93 -> 2466 | G9: =Raw!H93 -> 2432 | H9: =H56 -> 2653.7836 | I9: =I56 -> 2813.0107 | J9: =J56 -> 2981.7913 | K9: =K56 -> 3160.6988 | L9: =L56 -> 3350.3407 | M9: =M56 -> 3551.3611
A10: Inventories | B10: =Raw!C94 -> 55.6 | C10: =Raw!D94 -> 52 | D10: =Raw!E94 -> 52.8 | E10: =Raw!F94 -> 56 | F10: =Raw!G94 -> 61 | G10: =Raw!H94 -> 61 | H10: =H58 -> 63.525 | I10: =I58 -> 67.307463 | J10: =J58 -> 71.345911 | K10: =K58 -> 75.626666 | L10: =L58 -> 80.164266 | M10: =M58 -> 84.974121
A11: Prepaid expenses and other current assets | B11: =Raw!C95 -> 511.3 | C11: =Raw!D95 -> 673.4 | D11: =Raw!E95 -> 866.3 | E11: =Raw!F95 -> 1074 | F11: =Raw!G95 -> 863 | G11: =Raw!H95 -> 1046 | H11: =H60 -> 903.65837 | I11: =I60 -> 957.87788 | J11: =J60 -> 1015.3505 | K11: =K60 -> 1076.2716 | L11: =L60 -> 1140.8479 | M11: =M60 -> 1209.2987
A12: Total Current assets | B12: =SUM(B8:B11) -> 7148.5 | C12: =SUM(C8:C11) -> 5424.2 | D12: =SUM(D8:D11) -> 7986.4 | E12: =SUM(E8:E11) -> 4598 | F12: =SUM(F8:F11) -> 4164 | G12: =SUM(G8:G11) -> 4709 | H12: =SUM(H8:H11) -> 7266.6613 | I12: =SUM(I8:I11) -> 7577.0633 | ... M12: =SUM(M8:M11) -> 12258.257
A13: Investments in and advances to affiliates | B13: =Raw!C97 -> 1201.2 | C13: =Raw!D97 -> 1064.5 | D13: =Raw!E97 -> 1080.2 | E13: =Raw!F97 -> 2710 | F13: =Raw!G97 -> 2820 | G13: =Raw!H97 -> 2865 | H13: =G13 -> 2865 | I13: =H13 -> 2865 | J13: =I13 -> 2865 | K13: =J13 -> 2865 | L13: =K13 -> 2865 | M13: =L13 -> 2865
A14: PPE-Net property and equipment | B14: =Raw!C98 -> 24720.6 | C14: =Raw!D98 -> 23773.6 | D14: =Raw!E98 -> 24907.6 | E14: =Raw!F98 -> 25295 | F14: =Raw!G98 -> 28241 | G14: =Raw!H98 -> 28245 | H14: ='Fixed Assets Schedule'!H10 -> 29009.047 | I14: ='Fixed Assets Schedule'!I10 -> 30009.011 | J14: ='Fixed Assets Schedule'!J10 -> 31120.947 | K14: ='Fixed Assets Schedule'!K10 -> 32347.925 | L14: ='Fixed Assets Schedule'!L10 -> 33693.456 | M14: ='Fixed Assets Schedule'!M10 -> 35161.501
A15: Goodwill | B15: =Raw!C99 -> 2782.5 | C15: =Raw!D99 -> 2900.4 | D15: =Raw!E99 -> 3040.4 | E15: =Raw!F99 -> 3145 | F15: =Raw!G99 -> 3354 | G15: =Raw!H99 -> 3349 | H15: =G15 -> 3349 | I15: =H15 -> 3349 | J15: =I15 -> 3349 | K15: =J15 -> 3349 | L15: =K15 -> 3349 | M15: =L15 -> 3349
A16: Other Non-Current Assets | B16: =Raw!C100 -> 18001.5 | C16: =Raw!D100 -> 17272.9 | D16: =Raw!E100 -> 19132.2 | E16: =Raw!F100+2 -> 19436 | F16: =Raw!G100+1 -> 20938 | G16: =Raw!H100+1 -> 20871 | H16: =G16 -> 20871 | I16: =H16 -> 20871 | J16: =I16 -> 20871 | K16: =J16 -> 20871 | L16: =K16 -> 20871 | M16: =L16 -> 20871
A17: Other Intangible Assets | B17: =Raw!C101 -> 0 | C17: =Raw!D101 -> 0 | D17: =Raw!E101 -> 0 | E17: =Raw!F101 -> 0 | F17: =Raw!G101 -> 0 | G17: =Raw!H101 -> 0 | H17: 0 | I17: 0 | J17: 0 | K17: 0 | L17: 0 | M17: 0
A18: Total Assets | B18: =SUM(B12:B17) -> 53854.3 | C18: =SUM(C12:C17) -> 50435.6 | D18: =SUM(D12:D17) -> 56146.8 | E18: =SUM(E12:E17) -> 55184 | F18: =SUM(F12:F17) -> 59517 | G18: =SUM(G12:G17) -> 60039 | H18: =SUM(H12:H17) -> 63360.708 | I18: =SUM(I12:I17) -> 64671.074 | ... M18: =SUM(M12:M17) -> 74504.757
A20: Current Liabilities
A21: Accounts payable and accrued expenses | B21: =Raw!C105 -> 1006.8 | C21: =Raw!D105 -> 980.2 | D21: =Raw!E105 -> 1102.9 | E21: =Raw!F105 -> 1029 | F21: =Raw!G105 -> 1149 | G21: =Raw!H105 -> 1091 | H21: =H64 -> 1206.1085 | I21: =I64 -> 1277.9237 | J21: =J64 -> 1354.5992 | K21: =K64 -> 1435.8751 | L21: =L64 -> 1522.0276 | M21: =M64 -> 1613.3493
A22: Accrued Interest | B22: =Raw!C106 -> 363.3 | C22: =Raw!D106 -> 393.4 | D22: =Raw!E106 -> 468.9 | E22: =Raw!F106 -> 482 | F22: =Raw!G106 -> 533 | G22: =Raw!H106 -> 448 | H22: =G22 -> 448 | I22: =H22 -> 448 | J22: =I22 -> 448 | K22: =J22 -> 448 | L22: =K22 -> 448 | M22: =L22 -> 448
A23: Accrued Payroll & Other Liabilities | B23: =Raw!C107 -> 1347 | C23: =Raw!D107 -> 1237.4 | D23: =Raw!E107 -> 1433.6 | E23: =Raw!F107 -> 1129 | F23: =Raw!G107 -> 1488 | G23: =Raw!H107 -> 1257 | H23: =G23 -> 1257 | I23: =H23 -> 1257 | J23: =I23 -> 1257 | K23: =J23 -> 1257 | L23: =K23 -> 1257 | M23: =L23 -> 1257
A24: Short term borrowings & Current maturities of long-term debt | B24: =Raw!C108 -> 0 | C24: =Raw!D108 -> 0 | D24: =Raw!E108 -> 2192.4 | E24: =Raw!F108 -> 0 | F24: =Raw!G108 -> 0 | G24: =Raw!H108 -> 0 | H24: ='Debt Schedule'!H9 -> 3201 | I24: ='Debt Schedule'!I9 -> 5166 | J24: ='Debt Schedule'!J9 -> 3637 | K24: ='Debt Schedule'!K9 -> 3011 | L24: ='Debt Schedule'!L9 -> 0 | M24: ='Debt Schedule'!M9 -> 0
A25: Accrued income taxes | B25: =Raw!C109 -> 360.7 | C25: =Raw!D109 -> 274.9 | D25: =Raw!E109 -> 705.1 | E25: =Raw!F109 -> 361 | F25: =Raw!G109 -> 250 | G25: =Raw!H109 -> 391 | H25: =G25 -> 391 | I25: =H25 -> 391 | J25: =I25 -> 391 | K25: =J25 -> 391 | L25: =K25 -> 391 | M25: =L25 -> 391
A26: Other taxes | B26: =Raw!C110 -> 236.7 | C26: =Raw!D110 -> 255.1 | D26: =Raw!E110 -> 268 | E26: =Raw!F110 -> 224 | F26: =Raw!G110 -> 247 | G26: =Raw!H110 -> 253 | H26: =G26 -> 253 | I26: =H26 -> 253 | J26: =I26 -> 253 | K26: =J26 -> 253 | L26: =K26 -> 253 | M26: =L26 -> 253
A27: Lease liability | B27: =Raw!C111 -> 705.5 | C27: =Raw!D111 -> 661.1 | D27: =Raw!E111 -> 688.1 | E27: =Raw!F111 -> 636 | F27: =Raw!G111 -> 694 | G27: =Raw!H111 -> 707 | H27: =G27 -> 707 | I27: =H27 -> 707 | J27: =I27 -> 707 | K27: =J27 -> 707 | L27: =K27 -> 707 | M27: =L27 -> 707
A29: Total Current Liabilities | B29: =SUM(B21:B27) -> 4020 | C29: =SUM(C21:C27) -> 3802.1 | D29: =SUM(D21:D27) -> 6859 | E29: =SUM(E21:E27) -> 3861 | F29: =SUM(F21:F27) -> 4361 | G29: =SUM(G21:G27) -> 4147 | H29: =SUM(H21:H27) -> 7463.1085 | I29: =SUM(I21:I27) -> 9499.9237 | ... M29: =SUM(M21:M27) -> 4669.3493
A31: Long term Debt | B31: =Raw!C113 -> 35622.7 | C31: =Raw!D113 -> 35903.5 | D31: =Raw!E113 -> 37152.9 | E31: =Raw!F113 -> 38424 | F31: =Raw!G113 -> 39973 | G31: =Raw!H113 -> 40105 | H31: ='Debt Schedule'!H10 -> 36904 | I31: ='Debt Schedule'!I10 -> 31738 | J31: ='Debt Schedule'!J10 -> 28101 | K31: ='Debt Schedule'!K10 -> 25090 | L31: ='Debt Schedule'!L10 -> 25090 | M31: ='Debt Schedule'!M10 -> 25090
A32: Long-term lease liability | B32: =Raw!C114 -> 13020.9 | C32: =Raw!D114 -> 12134.4 | D32: =Raw!E114 -> 13057.7 | E32: =Raw!F114 -> 12888 | F32: =Raw!G114 -> 14147 | G32: =Raw!H114 -> 14069 | H32: =G32 -> 14069 | I32: =H32 -> 14069 | J32: =I32 -> 14069 | K32: =J32 -> 14069 | L32: =K32 -> 14069 | M32: =L32 -> 14069
A33: Long-term income taxes | B33: =Raw!C115 -> 1896.8 | C33: =Raw!D115 -> 791.9 | D33: =Raw!E115 -> 363.2 | E33: =Raw!F115 -> 344 | F33: =Raw!G115 -> 139 | G33: =Raw!H115 -> 151 | H33: =G33 -> 151 | I33: =H33 -> 151 | J33: =I33 -> 151 | K33: =J33 -> 151 | L33: =K33 -> 151 | M33: =L33 -> 151
A34: Deferred Income Taxes | B34: =Raw!C116 -> 2075.6 | C34: =Raw!D116 -> 1997.5 | D34: =Raw!E116 -> 1680.9 | E34: =Raw!F116 -> 1914 | F34: =Raw!G116 -> 1038 | G34: =Raw!H116 -> 1220 | H34: =G34 -> 1220 | I34: =H34 -> 1220 | J34: =I34 -> 1220 | K34: =J34 -> 1220 | L34: =K34 -> 1220 | M34: =L34 -> 1220
A35: Deferred revenues - initial franchise fees | B35: =Raw!C117 -> 738.3 | C35: =Raw!D117 -> 757.8 | D35: =Raw!E117 -> 790.1 | E35: =Raw!F117 -> 778 | F35: =Raw!G117 -> 945 | G35: =Raw!H117 -> 946 | H35: =G35 -> 946 | I35: =H35 -> 946 | J35: =I35 -> 946 | K35: =J35 -> 946 | L35: =K35 -> 946 | M35: =L35 -> 946
A36: Other long-term Liabilities | B36: =Raw!C118 -> 1081 | C36: =Raw!D118 -> 1051.8 | D36: =Raw!E118 -> 949.7 | E36: =Raw!F118 -> 771 | F36: =Raw!G118 -> 704 | G36: =Raw!H118 -> 686 | H36: =G36 -> 686 | I36: =H36 -> 686 | J36: =I36 -> 686 | K36: =J36 -> 686 | L36: =K36 -> 686 | M36: =L36 -> 686
A37: Total Liabilities | B37: =SUM(B29:B36) -> 58455.3 | C37: =SUM(C29:C36) -> 56439 | D37: =SUM(D29:D36) -> 60853.5 | E37: =SUM(E29:E36) -> 58980 | F37: =SUM(F29:F36) -> 61307 | G37: =SUM(G29:G36) -> 61324 | H37: =SUM(H29:H36) -> 61439.109 | I37: =SUM(I29:I36) -> 58309.924 | ... M37: =SUM(M29:M36) -> 46831.349
A39: McDONALD’S CORPORATION Shareholders' Equity
A40: Common stock, $0.01 par value | B40: =Raw!C122 -> 16.6 | C40: =Raw!D122 -> 16.6 | D40: =Raw!E122 -> 16.6 | E40: =Raw!F122 -> 17 | F40: =Raw!G122 -> 17 | G40: =Raw!H122 -> 17 | H40: =G40 -> 17 | I40: =H40 -> 17 | J40: =I40 -> 17 | K40: =J40 -> 17 | L40: =K40 -> 17 | M40: =L40 -> 17
A41: Capital surplus | B41: =Raw!C123 -> 8231.6 | C41: =Raw!D123 -> 8547.1 | D41: =Raw!E123 -> 8892.9 | E41: =Raw!F123 -> 9281 | F41: =Raw!G123 -> 9641 | G41: =Raw!H123 -> 9792 | H41: =G41+'McD IS'!H95 -> 9946.1179 | I41: =H41+'McD IS'!J95 -> 10157.918 | J41: =I41+'McD IS'!K95 -> 10382.426 | K41: =J41+'McD IS'!L95 -> 10620.404 | L41: =K41+'McD IS'!M95 -> 10872.661 | M41: =L41+'McD IS'!N95 -> 11140.053
A42: Reinvested earnings | B42: =Raw!C124 -> 57534.7 | C42: =Raw!D124 -> 59543.9 | D42: =Raw!E124 -> 63479.9 | E42: =Raw!F124 -> 66834 | F42: =Raw!G124 -> 70282 | G42: =Raw!H124 -> 70942 | H42: =G42+('McD IS'!H59-'McD IS'!H61) -> 73994.482 | I42: =H42+('McD IS'!J59-'McD IS'!J61) -> 78222.233 | J42: =I42+('McD IS'!K59-'McD IS'!K61) -> 82778.896 | K42: =J42+('McD IS'!L59-'McD IS'!L61) -> 87683.823 | L42: =K42+('McD IS'!M59-'McD IS'!M61) -> 92942.365 | M42: =L42+('McD IS'!N59-'McD IS'!N61) -> 98552.355
A43: Accumulated other comprehensive income (loss) | B43: =Raw!C125 -> -2573.7 | C43: =Raw!D125 -> -2486.6 | D43: =Raw!E125 -> -2456 | E43: =Raw!F125 -> -2553 | F43: =Raw!G125 -> -2414 | G43: =Raw!H125 -> -2363 | H43: =G43 -> -2363 | I43: =H43 -> -2363 | J43: =I43 -> -2363 | K43: =J43 -> -2363 | L43: =K43 -> -2363 | M43: =L43 -> -2363
A44: Treasury stock, (shares bought by the company) ,at cost | B44: =Raw!C126 -> -67810.2 | C44: =Raw!D126 -> -71624.4 | D44: =Raw!E126 -> -74640.1 | E44: =Raw!F126 -> -77375 | F44: =Raw!G126 -> -79316 | G44: =Raw!H126 -> -79673 | H44: =G44 -> -79673 | I44: =H44 -> -79673 | J44: =I44 -> -79673 | K44: =J44 -> -79673 | L44: =K44 -> -79673 | M44: =L44 -> -79673
A45: Equity Attributable to Shreholders' of McDONALD’S CORPORATION | B45: =SUM(B40:B44) -> -4601 | C45: =SUM(C40:C44) -> -6003.4 | D45: =SUM(D40:D44) -> -4706.7 | E45: =SUM(E40:E44) -> -3796 | F45: =SUM(F40:F44) -> -1790 | G45: =SUM(G40:G44) -> -1285 | H45: =SUM(H40:H44) -> 1921.5997 | I45: =SUM(I40:I44) -> 6361.1506 | ... M45: =SUM(M40:M44) -> 27673.408
...

Sheet McD-CFS
A1: McDONALD’S CORPORATION
A2: (in USD million except per Share Data)
A3: Cash Flow Statement | H3: 9 | I3: 12 | J3: 12 | K3: 12 | L3: 12 | M3: 12
H4: 46387 | I4: 46752 | J4: 47118 | K4: 47483 | L4: 47848 | M4: 48213
A6: Cash From Operating Activities
A7: Net Income (Consolidated) | H7: ='McD IS'!H52 -> 8036.6623 | I7: ='McD IS'!J52 -> 11130.945 | J7: ='McD IS'!K52 -> 11996.914 | K7: ='McD IS'!L52 -> 12913.835 | L7: ='McD IS'!M52 -> 13844.841 | M7: ='McD IS'!N52 -> 14770.143
A8: Add: Depreciation and amortization | H8: ='Fixed Assets Schedule'!H9 -> 1611.7207 | I8: ='Fixed Assets Schedule'!I9 -> 2264.9842 | J8: ='Fixed Assets Schedule'!J9 -> 2348.9096 | K8: ='Fixed Assets Schedule'!K9 -> 2441.518 | L8: ='Fixed Assets Schedule'!L9 -> 2543.0744 | M8: ='Fixed Assets Schedule'!M9 -> 2653.8777
A9: Add: Share-based compensation expense | H9: ='McD IS'!H95 -> 154.11794 | I9: ='McD IS'!J95 -> 211.7998 | J9: ='McD IS'!K95 -> 224.50778 | K9: ='McD IS'!L95 -> 237.97825 | L9: ='McD IS'!M95 -> 252.25695 | M9: ='McD IS'!N95 -> 267.39236
A10: Add: Interest Expense | H10: ='Debt Schedule'!H13 -> 1152.9111 | I10: ='Debt Schedule'!I13 -> 1475.868 | J10: ='Debt Schedule'!J13 -> 1315.5155 | K10: ='Debt Schedule'!K13 -> 1146.8071 | L10: ='Debt Schedule'!L13 -> 1019.399 | M10: ='Debt Schedule'!M13 -> 961.69354
A11: Minus: Changes in NWC | H11: =-'McD-BS'!H68 -> 33.14153 | I11: =-'McD-BS'!I68 -> -145.41378 | J11: =-'McD-BS'!J68 -> -153.61634 | K11: =-'McD-BS'!K68 -> -162.83332 | L11: =-'McD-BS'!L68 -> -172.60331 | M11: =-'McD-BS'!M68 -> -182.95951
A12: Net Cash Provided by Operating Activities | H12: =SUM(H7:H11) -> 10988.554 | I12: =SUM(I7:I11) -> 14938.184 | J12: =SUM(J7:J11) -> 15732.231 | K12: =SUM(K7:K11) -> 16577.305 | L12: =SUM(L7:L11) -> 17486.968 | M12: =SUM(M7:M11) -> 18470.148
A14: Cash From Investing Activities
A15: Capital Expenditure | H15: =-'Fixed Assets Schedule'!H7 -> -2375.7677 | I15: =-'Fixed Assets Schedule'!I7 -> -3264.9484 | J15: =-'Fixed Assets Schedule'!J7 -> -3460.8453 | K15: =-'Fixed Assets Schedule'!K7 -> -3668.496 | L15: =-'Fixed Assets Schedule'!L7 -> -3888.6058 | M15: =-'Fixed Assets Schedule'!M7 -> -4121.9221
A17: Net Cash Used for Investing Activities | H17: =H15 -> -2375.7677 | I17: =I15 -> -3264.9484 | J17: =J15 -> -3460.8453 | K17: =K15 -> -3668.496 | L17: =L15 -> -3888.6058 | M17: =M15 -> -4121.9221
A19: Cash From Financing Activities
A20: Cash dividends paid | H20: =-'McD IS'!H61 -> -4984.1805 | I20: =-'McD IS'!J61 -> -6903.1942 | J20: =-'McD IS'!K61 -> -7440.2512 | K20: =-'McD IS'!L61 -> -8008.9071 | L20: =-'McD IS'!M61 -> -8586.2988 | M20: =-'McD IS'!N61 -> -9160.1536
A21: Debt Raised | H21: ='Debt Schedule'!H7 -> 0 | I21: ='Debt Schedule'!I7 -> 0 | J21: ='Debt Schedule'!J7 -> 0 | K21: ='Debt Schedule'!K7 -> 0 | L21: ='Debt Schedule'!L7 -> 0 | M21: ='Debt Schedule'!M7 -> 0
A22: Debt Repaid | H22: =-'Debt Schedule'!H6 -> 0 | I22: =-'Debt Schedule'!I6 -> -3201 | J22: =-'Debt Schedule'!J6 -> -5166 | K22: =-'Debt Schedule'!K6 -> -3637 | L22: =-'Debt Schedule'!L6 -> -3011 | M22: =-'Debt Schedule'!M6 -> 0
A23: Interest Expense | H23: =-'Debt Schedule'!H13 -> -1152.9111 | I23: =-'Debt Schedule'!I13 -> -1475.868 | J23: =-'Debt Schedule'!J13 -> -1315.5155 | K23: =-'Debt Schedule'!K13 -> -1146.8071 | L23: =-'Debt Schedule'!L13 -> -1019.399 | M23: =-'Debt Schedule'!M13 -> -961.69354
A24: Net Cash Provided by/(Used for) Financing Activities | H24: =SUM(H20:H23) -> -6137.0916 | I24: =SUM(I20:I23) -> -11580.062 | J24: =SUM(J20:J23) -> -13921.767 | K24: =SUM(K20:K23) -> -12792.714 | L24: =SUM(L20:L23) -> -12616.698 | M24: =SUM(M20:M23) -> -10121.847
A26: Net Increase/(Decrease) in Cash and Cash Equivalents | H26: =SUM(H12,H17,H24) -> 2475.6943 | I26: =SUM(I12,I17,I24) -> 93.172992 | J26: =SUM(J12,J17,J24) -> -1650.3811 | K26: =SUM(K12,K17,K24) -> 116.09426 | L26: =SUM(L12,L17,L24) -> 981.66394 | M26: =SUM(M12,M17,M24) -> 4226.3783
A27: Cash and Cash Equivalents, Beginning of Year | H27: ='McD-BS'!G7 -> 1170 | I27: =H28 -> 3645.6943 | J27: =I28 -> 3738.8673 | K27: =J28 -> 2088.4862 | L27: =K28 -> 2204.5804 | M27: =L28 -> 3186.2444
A28: Cash and Cash Equivalents, End of Period | H28: =SUM(H26,H27) -> 3645.6943 | I28: =SUM(I26,I27) -> 3738.8673 | J28: =SUM(J26,J27) -> 2088.4862 | K28: =SUM(K26,K27) -> 2204.5804 | L28: =SUM(L26,L27) -> 3186.2444 | M28: =SUM(M26,M27) -> 7412.6227

Sheet Debt Schedule
A1: McDONALD’S CORPORATION
A2: (in USD million except per Share Data)
A3: Debt Schedule | H3: 9 | I3: 12 | J3: 12 | K3: 12 | L3: 12 | M3: 12
H4: 46387 | I4: 46752 | J4: 47118 | K4: 47483 | L4: 47848 | M4: 48213
A5: Opening Debt | H5: ='McD-BS'!G31+'McD-BS'!G24 -> 40105 | I5: =H8 -> 40105 | J5: =I8 -> 36904 | K5: =J8 -> 31738 | L5: =K8 -> 28101 | M5: =L8 -> 25090
A6: Less: Mandatory Debt Repayments | H6: 0 | I6: =Raw!D150 -> 3201 | J6: =Raw!E150 -> 5166 | K6: =Raw!F150 -> 3637 | L6: =Raw!G150 -> 3011 | M6: =Raw!H150 -> 0
A7: Add: debt raised | H7: 0 | I7: 0 | J7: 0 | K7: 0 | L7: 0 | M7: 0
A8: Closing Total Debt | H8: =H5-H6+H7 -> 40105 | I8: =I5-I6+I7 -> 36904 | J8: =J5-J6+J7 -> 31738 | K8: =K5-K6+K7 -> 28101 | L8: =L5-L6+L7 -> 25090 | M8: =M5-M6+M7 -> 25090
A9: Current portion of long term debt | H9: =I6 -> 3201 | I9: =J6 -> 5166 | J9: =K6 -> 3637 | K9: =L6 -> 3011 | L9: 0 | M9: 0
A10: Long term debt + Short Term Debt | H10: =H8-H9 -> 36904 | I10: =I8-I9 -> 31738 | J10: =J8-J9 -> 28101 | K10: =K8-K9 -> 25090 | L10: =L8-L9 -> 25090 | M10: =M8-M9 -> 25090
A13: Interest Expense | H13: =H15*AVERAGE(H5,H8)*0.75 -> 1152.9111 | I13: =$H$15*AVERAGE(I5,I8) -> 1475.868 | J13: =$H$15*AVERAGE(J5,J8) -> 1315.5155 | K13: =$H$15*AVERAGE(K5,K8) -> 1146.8071 | L13: =$H$15*AVERAGE(L5,L8) -> 1019.399 | M13: =$H$15*AVERAGE(M5,M8) -> 961.69354
A15: Average Interest Rate | H15: =Raw!F146 -> 0.038329755

Sheet Fixed Assets Schedule
A1: McDONALD’S CORPORATION
A2: (in USD million except per Share Data)
A3: Property, Plant & Equipment | B3: 12 | C3: 12 | D3: 12 | E3: 12 | F3: 12 | G3: 3 | H3: 9 | I3: 12 | J3: 12 | K3: 12 | L3: 12 | M3: 12
B4: 44561 | C4: 44926 | D4: 45291 | E4: 45657 | F4: 46022 | G4: 46112 | H4: 46387 | I4: 46752 | J4: 47118 | K4: 47483 | L4: 47848 | M4: 48213
A6: Opening Balance-WDV | C6: =B10 -> 24720.6 | D6: =C10 -> 23773.6 | E6: =D10 -> 24907.6 | F6: =E10 -> 25295 | G6: =F10 -> 28241 | H6: =G10 -> 28245 | I6: =H10 -> 29009.047 | J6: =I10 -> 30009.011 | ... M6: =L10 -> 33693.456
A7: Add: Net Addition during the Period | C7: =C8-C6 -> 877.4 | D7: =D8-D6 -> 3016.7 | E7: =E8-E6 -> 2334.4 | F7: =F8-F6 -> 5003 | G7: =G8-G6 -> 545.86558 | H7: ='McD IS'!H8*'Fixed Assets Schedule'!H14 -> 2375.7677 | I7: ='McD IS'!J8*'Fixed Assets Schedule'!$H$14 -> 3264.9484 | J7: ='McD IS'!K8*'Fixed Assets Schedule'!$H$14 -> 3460.8453 | K7: ='McD IS'!L8*'Fixed Assets Schedule'!$H$14 -> 3668.496 | L7: ='McD IS'!M8*'Fixed Assets Schedule'!$H$14 -> 3888.6058 | M7: ='McD IS'!N8*'Fixed Assets Schedule'!$H$14 -> 4121.9221
A8: Total Depreciable Assets During the Year | B8: =B10+B9 -> 26581 | C8: =C10+C9 -> 25598 | D8: =D10+D9 -> 26790.3 | E8: =E10+E9 -> 27242 | F8: =F10+F9 -> 30298 | G8: =G10+G9 -> 28786.866 | H8: =H6+H7 -> 30620.768 | I8: =I6+I7 -> 32273.995 | J8: =J6+J7 -> 33469.856 | K8: =K6+K7 -> 34789.443 | L8: =L6+L7 -> 36236.531 | M8: =M6+M7 -> 37815.378
A9: Less: Depreciation during the year | B9: ='McD IS'!B31 -> 1860.4 | C9: ='McD IS'!C31 -> 1824.4 | D9: ='McD IS'!D31 -> 1882.7 | E9: ='McD IS'!E31 -> 1947 | F9: ='McD IS'!F31 -> 2057 | G9: ='McD IS'!G31 -> 541.86558 | H9: =H8*H15*0.75 -> 1611.7207 | I9: =I8*$H$15 -> 2264.9842 | J9: =J8*$H$15 -> 2348.9096 | K9: =K8*$H$15 -> 2441.518 | L9: =L8*$H$15 -> 2543.0744 | M9: =M8*$H$15 -> 2653.8777
A10: Closing Balance-WDV | B10: ='McD-BS'!B14 -> 24720.6 | C10: ='McD-BS'!C14 -> 23773.6 | D10: ='McD-BS'!D14 -> 24907.6 | E10: ='McD-BS'!E14 -> 25295 | F10: ='McD-BS'!F14 -> 28241 | G10: ='McD-BS'!G14 -> 28245 | H10: =H8-H9 -> 29009.047 | I10: =I8-I9 -> 30009.011 | J10: =J8-J9 -> 31120.947 | K10: =K8-K9 -> 32347.925 | L10: =L8-L9 -> 33693.456 | M10: =M8-M9 -> 35161.501
A12: Capex as % of Opening PPE
A13: PPE Turnover Ratio = Net Oper rev (Norm.)/Total Depreciable Assets | B13: ='McD IS'!B8/'Fixed Assets Schedule'!B8 -> 0.8736654 | C13: ='McD IS'!C8/'Fixed Assets Schedule'!C8 -> 0.90564107 | D13: ='McD IS'!D8/'Fixed Assets Schedule'!D8 -> 0.95160189 | E13: ='McD IS'!E8/'Fixed Assets Schedule'!E8 -> 0.95147199 | F13: ='McD IS'!F8/'Fixed Assets Schedule'!F8 -> 0.8873523 | G13: ='McD IS'!G8/'Fixed Assets Schedule'!G8 -> 0.22638797 | H13: =AVERAGE(B13:F13) -> 0.91394653
A14: Capex as % of Sales | C14: =C7/'McD IS'!C8 -> 0.037847351 | D14: =D7/'McD IS'!D8 -> 0.1183312 | E14: =E7/'McD IS'!E8 -> 0.090061728 | F14: =F7/'McD IS'!F8 -> 0.1860889 | G14: =G7/'McD IS'!G8 -> 0.083760255 | H14: =AVERAGE(C14:F14) -> 0.10808229
A15: Depreciation Rate = Dep / TDA | B15: =B9/B8 -> 0.069989842 | C15: =C9/C8 -> 0.071271193 | D15: =D9/D8 -> 0.070275436 | E15: =E9/E8 -> 0.071470523 | F15: =F9/F8 -> 0.06789227 | G15: =G9/G8 -> 0.018823362 | H15: =AVERAGE(B15:F15) -> 0.070179853
A18: Depreciation (Operational)
A19: Depreciation (Corporate)
A20: Total Depreciation
A21: % Dep. Operational
A22: % Dep. Corporate
A24: written down value - asset value after reducing depreciation

Sheet Beta
C2: BETA CALCULATION
C4: Competitors | D4: Beta | E4: Market Cap | F4: R sq
C5: McDonald's | D5: =SLOPE($D$16:$D$171,$AB$16:$AB$171) -> 0.30143553 | F5: =RSQ($D$16:$D$171,$AB$16:$AB$171) -> 0.062572524
C6: Yum! Brands | D6: =SLOPE($H$17:$H$172,$AB$17:$AB$172) -> 0.34717764 | F6: =RSQ($H$16:$H$171,$AB$16:$AB$171) -> 0.06100843
C7: Restaurant Brands International | D7: =SLOPE($L$16:$L$171,$AB$16:$AB$171) -> 0.38570636 | F7: =RSQ($L$16:$L$171,$AB$16:$AB$171) -> 0.073377092
C8: Domino's Pizza | D8: =SLOPE($P$16:$P$171,$AB$16:$AB$171) -> 0.74374466 | F8: =RSQ($P$16:$P$171,$AB$16:$AB$171) -> 0.14458303
C9: Wendy's | D9: =SLOPE($T$16:T171,$AB$16:AB171) -> 0.41934942 | F9: =RSQ($T$16:V171,$AB$16:AD171) -> 0.04860569
C10: Chipotle (CMG) | D10: =SLOPE($X$16:X171,$AB$16:AB171) -> 0.93395764 | F10: =RSQ($X$16:Z171,$AB$16:AD171) -> 0.1674113
C12: Source : marketscreener.com, investing.com & yahoo finance
B14: McDonald's | F14: Yum! Brands | J14: Restaurant Brands International | N14: Domino's Pizza | R14: Wendy's | V14: Chipotle (CMG) | Z14: S&P 500
B15: Date | C15: Adj Close | D15: % Change | F15: Date | G15: Adj Close | H15: % Change | J15: Date | K15: Adj Close | L15: % Change | N15: Date | O15: Adj Close | P15: % Change | R15: Date | S15: Adj Close | T15: % Change | V15: Date | W15: Adj Close | X15: % Change | Z15: Date | AA15: Adj Close | AB15: % Change
B16: 06-28-2026 | C16: 267.11 | D16: =C16/C17-1 -> -0.0098235469 | F16: 46201 | G16: 158.24 | H16: =G16/G17-1 -> 0.011700019 | J16: 06-28-2026 | K16: 72.77 | L16: =K16/K17-1 -> -0.021119182 | N16: 06-28-2026 | O16: 289.39 | P16: =O16/O17-1 -> -0.029478838 | R16: 06-28-2026 | S16: 8.12 | T16: =S16/S17-1 -> 0.041025641 | V16: 06-28-2026 | W16: 32.85 | X16: =W16/W17-1 -> -0.014697061 | Z16: 06-28-2026 | AA16: 7440.43 | AB16: =AA16/AA17-1 -> 0.011750036
B17: 06-21-2026 | C17: 269.76 | D17: =C17/C18-1 -> -0.031764833 | F17: 46194 | G17: 156.41 | H17: =G17/G18-1 -> 0.029080861 | J17: 06-21-2026 | K17: 74.34 | L17: =K17/K18-1 -> 0.012254902 | N17: 06-21-2026 | O17: 298.18 | P17: =O17/O18-1 -> -0.04573239 | R17: 06-21-2026 | S17: 7.8 | T17: =S17/S18-1 -> 0.14705882 | V17: 06-21-2026 | W17: 33.34 | X17: =W17/W18-1 -> 0.026161896 | Z17: 46194 | AA17: 7354.02 | AB17: =AA17/AA18-1 -> -0.019539822
B18: 06-14-2026 | C18: 278.61 | D18: =C18/C19-1 -> -0.021768899 | F18: 46187 | G18: 151.99 | H18: =G18/G19-1 -> -0.01503467 | J18: 06-14-2026 | K18: 73.44 | L18: =K18/K19-1 -> -0.018837675 | N18: 06-14-2026 | O18: 312.47 | P18: =O18/O19-1 -> -0.035229097 | R18: 06-14-2026 | S18: 6.8 | T18: =S18/S19-1 -> 0.0014727541 | V18: 06-14-2026 | W18: 32.49 | X18: =W18/W19-1 -> 0.0080670183 | Z18: 46187 | AA18: 7500.58 | AB18: =AA18/AA19-1 -> 0.0093009987
B19: 46209 | C19: 284.81 | D19: =C19/C20-1 -> 0.017760149 | F19: 46180 | G19: 154.31 | H19: =G19/G20-1 -> 0.022801087 | J19: 46209 | K19: 74.85 | L19: =K19/K20-1 -> 0.03014038 | N19: 46209 | O19: 323.88 | P19: =O19/O20-1 -> 0.031497818 | R19: 46209 | S19: 6.79 | T19: =S19/S20-1 -> 0.011922504 | V19: 46209 | W19: 32.23 | X19: =W19/W20-1 -> 0.098500341 | Z19: 46180 | AA19: 7431.46 | AB19: =AA19/AA20-1 -> 0.0064628495
B20: 05-31-2026 | C20: 279.84 | D20: =C20/C21-1 -> 0.0022922636 | F20: 46173 | G20: 150.87 | H20: =G20/G21-1 -> 0.019736397 | J20: 05-31-2026 | K20: 72.66 | L20: =K20/K21-1 -> -0.027309237 | N20: 05-31-2026 | O20: 313.99 | P20: =O20/O21-1 -> 0.010979458 | R20: 05-31-2026 | S20: 6.71 | T20: =S20/S21-1 -> -0.12857143 | V20: 05-31-2026 | W20: 29.34 | X20: =W20/W21-1 -> -0.079096045 | Z20: 46173 | AA20: 7383.74 | AB20: =AA20/AA21-1 -> -0.025899531
B21: 05-24-2026 | C21: 279.2 | D21: =C21/C22-1 -> -0.010876112 | F21: 46166 | G21: 147.95 | H21: =G21/G22-1 -> -0.046406703 | J21: 05-24-2026 | K21: 74.7 | L21: =K21/K22-1 -> -0.0090209605 | N21: 05-24-2026 | O21: 310.58 | P21: =O21/O22-1 -> -0.018766587 | R21: 05-24-2026 | S21: 7.7 | T21: =S21/S22-1 -> -0.014084507 | V21: 05-24-2026 | W21: 31.86 | X21: =W21/W22-1 -> -0.03131651 | Z21: 46166 | AA21: 7580.06 | AB21: =AA21/AA22-1 -> 0.014262451
B22: 05-17-2026 | C22: 282.27 | D22: =C22/C23-1 -> 0.021274286 | F22: 46159 | G22: 155.15 | H22: =G22/G23-1 -> 0.034540241 | J22: 05-17-2026 | K22: 75.38 | L22: =K22/K23-1 -> -0.0060654008 | N22: 05-17-2026 | O22: 316.52 | P22: =O22/O23-1 -> 0.047074002 | R22: 05-17-2026 | S22: 7.81 | T22: =S22/S23-1 -> -0.026184539 | V22: 05-17-2026 | W22: 32.89 | X22: =W22/W23-1 -> 0.0073506891 | Z22: 46159 | AA22: 7473.47 | AB22: =AA22/AA23-1 -> 0.0087696565
B23: 46300 | C23: 276.39 | D23: =C23/C24-1 -> 0.0023209429 | F23: 46152 | G23: 149.97 | H23: =G23/G24-1 -> -0.013030602 | J23: 46300 | K23: 75.84 | L23: =K23/K24-1 -> -0.048550997 | N23: 46300 | O23: 302.29 | P23: =O23/O24-1 -> -0.065506368 | R23: 46300 | S23: 8.02 | T23: =S23/S24-1 -> 0.098630137 | V23: 46300 | W23: 32.65 | X23: =W23/W24-1 -> 0.0049245922 | Z23: 46152 | AA23: 7408.5 | AB23: =AA23/AA24-1 -> 0.0012934303
B24: 46086 | C24: 275.75 | D24: =C24/C25-1 -> -0.037991906 | F24: 46145 | G24: 151.95 | H24: =G24/G25-1 -> -0.040477393 | J24: 46086 | K24: 79.71 | L24: =K24/K25-1 -> -0.0039985006 | N24: 46086 | O24: 323.48 | P24: =O24/O25-1 -> -0.042306895 | R24: 46086 | S24: 7.3 | T24: =S24/S25-1 -> 0.089552239 | V24: 46086 | W24: 32.49 | X24: =W24/W25-1 -> -0.014857489 | Z24: 46145 | AA24: 7398.93 | AB24: =AA24/AA25-1 -> 0.02334816
B25: 04-26-2026 | C25: 286.64 | D25: =C25/C26-1 -> -0.042490647 | F25: 46138 | G25: 158.36 | H25: =G25/G26-1 -> -0.011979037 | J25: 04-26-2026 | K25: 80.03 | L25: =K25/K26-1 -> -0.010754017 | N25: 04-26-2026 | O25: 337.77 | P25: =O25/O26-1 -> -0.081722535 | R25: 04-26-2026 | S25: 6.7 | T25: =S25/S26-1 -> -0.06162465 | V25: 04-26-2026 | W25: 32.98 | X25: =W25/W26-1 -> -0.035954399 | Z25: 46138 | AA25: 7230.12 | AB25: =AA25/AA26-1 -> 0.0090773585
B26: 04-19-2026 | C26: 299.36 | D26: =C26/C27-1 -> -0.038540596 | F26: 46131 | G26: 160.28 | H26: =G26/G27-1 -> -0.015418638 | J26: 04-19-2026 | K26: 80.9 | L26: =K26/K27-1 -> 0.032941777 | N26: 04-19-2026 | O26: 367.83 | P26: =O26/O27-1 -> -0.011369134 | R26: 04-19-2026 | S26: 7.14 | T26: =S26/S27-1 -> 0.027338129 | V26: 04-19-2026 | W26: 34.21 | X26: =W26/W27-1 -> -0.045213508 | Z26: 46131 | AA26: 7165.08 | AB26: =AA26/AA27-1 -> 0.0054756766
B27: 46360 | C27: 311.36 | D27: =C27/C28-1 -> 0.018581523 | F27: 46124 | G27: 162.79 | H27: =G27/G28-1 -> 0.006367458 | J27: 46360 | K27: 78.32 | L27: =K27/K28-1 -> 0.025265087 | N27: 46360 | O27: 372.06 | P27: =O27/O28-1 -> 0.01669627 | R27: 46360 | S27: 6.95 | T27: =S27/S28-1 -> 0.0087082729 | V27: 46360 | W27: 35.83 | X27: =W27/W28-1 -> 0.051041361 | Z27: 46124 | AA27: 7126.06 | AB27: =AA27/AA28-1 -> 0.045353526
B28: 46146 | C28: 305.68 | D28: =C28/C29-1 -> -0.0047535326 | F28: 46117 | G28: 161.76 | H28: =G28/G29-1 -> 0.036325197 | J28: 46146 | K28: 76.39 | L28: =K28/K29-1 -> -0.0024810656 | N28: 46146 | O28: 365.95 | P28: =O28/O29-1 -> -0.013133056 | R28: 46146 | S28: 6.89 | T28: =S28/S29-1 -> 0.0014534884 | V28: 46146 | W28: 34.09 | X28: =W28/W29-1 -> 0.028045838 | Z28: 46117 | AA28: 6816.89 | AB28: =AA28/AA29-1 -> 0.03557816
B29: 03-29-2026 | C29: 307.14 | D29: =C29/C30-1 -> 0.0040536123 | F29: 46110 | G29: 156.09 | H29: =G29/G30-1 -> 0.013834762 | J29: 03-29-2026 | K29: 76.58 | L29: =K29/K30-1 -> 0.07224867 | N29: 03-29-2026 | O29: 370.82 | P29: =O29/O30-1 -> 0.065146206 | R29: 03-29-2026 | S29: 6.88 | T29: =S29/S30-1 -> 0.011764706 | V29: 03-29-2026 | W29: 33.16 | X29: =W29/W30-1 -> 0.074530136 | Z29: 46110 | AA29: 6582.69 | AB29: =AA29/AA30-1 -> 0.03357592
B30: 03-22-2026 | C30: 305.9 | D30: =C30/C31-1 -> -0.0095515622 | F30: 46103 | G30: 153.96 | H30: =G30/G31-1 -> -0.01566396 | J30: 03-22-2026 | K30: 71.42 | L30: =K30/K31-1 -> -0.03159322 | N30: 03-22-2026 | O30: 348.14 | P30: =O30/O31-1 -> -0.067523771 | R30: 03-22-2026 | S30: 6.8 | T30: =S30/S31-1 -> -0.04090268 | V30: 03-22-2026 | W30: 30.86 | X30: =W30/W31-1 -> -0.075217261 | Z30: 46103 | AA30: 6368.85 | AB30: =AA30/AA31-1 -> -0.021152758
B31: 03-15-2026 | C31: 308.85 | D31: =C31/C32-1 -> -0.05394229 | F31: 46096 | G31: 156.41 | H31: =G31/G32-1 -> -0.024875312 | J31: 03-15-2026 | K31: 73.75 | L31: =K31/K32-1 -> 0.015141087 | N31: 03-15-2026 | O31: 373.35 | P31: =O31/O32-1 -> -0.070413067 | R31: 03-15-2026 | S31: 7.09 | T31: =S31/S32-1 -> -0.011157601 | V31: 03-15-2026 | W31: 33.37 | X31: =W31/W32-1 -> 0.026137761 | Z31: 46096 | AA31: 6506.48 | AB31: =AA31/AA32-1 -> -0.018954523
B32: 46237 | C32: 326.46 | D32: =C32/C33-1 -> -0.0048771566 | F32: 46089 | G32: 160.4 | H32: =G32/G33-1 -> 0.0025 | J32: 46237 | K32: 72.65 | L32: =K32/K33-1 -> -0.017977832 | N32: 46237 | O32: 401.63 | P32: =O32/O33-1 -> -0.016600965 | R32: 46237 | S32: 7.17 | T32: =S32/S33-1 -> -0.033692722 | V32: 46237 | W32: 32.52 | X32: =W32/W33-1 -> -0.08057676 | Z32: 46089 | AA32: 6632.19 | AB32: =AA32/AA33-1 -> -0.015998469
B33: 46025 | C33: 328.06 | D33: =C33/C34-1 -> -0.03811646 | F33: 46082 | G33: 160 | H33: =G33/G34-1 -> -0.048525214 | J33: 46025 | K33: 73.98 | L33: =K33/K34-1 -> 0.031655278 | N33: 46025 | O33: 408.41 | P33: =O33/O34-1 -> 0.014658021 | R33: 46025 | S33: 7.42 | T33: =S33/S34-1 -> -0.031331593 | V33: 46025 | W33: 35.37 | X33: =W33/W34-1 -> -0.04970446 | Z33: 46082 | AA33: 6740.02 | AB33: =AA33/AA34-1 -> -0.020186426
B34: 02-22-2026 | C34: 341.06 | D34: =C34/C35-1 -> 0.035932327 | F34: 46075 | G34: 168.16 | H34: =G34/G35-1 -> 0.029572032 | J34: 02-22-2026 | K34: 71.71 | L34: =K34/K35-1 -> 0.041993607 | N34: 02-22-2026 | O34: 402.51 | P34: =O34/O35-1 -> 0.046540652 | R34: 02-22-2026 | S34: 7.66 | T34: =S34/S35-1 -> -0.05315204 | V34: 02-22-2026 | W34: 37.22 | X34: =W34/W35-1 -> -0.0085242408 | Z34: 46075 | AA34: 6878.88 | AB34: =AA34/AA35-1 -> -0.0044330206
B35: 02-15-2026 | C35: 329.23 | D35: =C35/C36-1 -> 0.0050369375 | F35: 46068 | G35: 163.33 | H35: =G35/G36-1 -> 0.017188765 | J35: 02-15-2026 | K35: 68.82 | L35: =K35/K36-1 -> 0.040520109 | N35: 02-15-2026 | O35: 384.61 | P35: =O35/O36-1 -> 0.024260985 | R35: 02-15-2026 | S35: 8.09 | T35: =S35/S36-1 -> 0.081550802 | V35: 02-15-2026 | W35: 37.54 | X35: =W35/W36-1 -> 0.03415978 | Z35: 46068 | AA35: 6909.51 | AB35: =AA35/AA36-1 -> 0.010728229
B36: 46236 | C36: 327.58 | D36: =C36/C37-1 -> 0.0012837755 | F36: 46061 | G36: 160.57 | H36: =G36/G37-1 -> -0.014484748 | J36: 46236 | K36: 66.14 | L36: =K36/K37-1 -> -0.067136812 | N36: 46236 | O36: 375.5 | P36: =O36/O37-1 -> -0.049078201 | R36: 46236 | S36: 7.48 | T36: =S36/S37-1 -> -0.067331671 | V36: 46236 | W36: 36.3 | X36: =W36/W37-1 -> -0.078446306 | Z36: 46061 | AA36: 6836.17 | AB36: =AA36/AA37-1 -> -0.013866971
B37: 46024 | C37: 327.16 | D37: =C37/C38-1 -> 0.038603175 | F37: 46054 | G37: 162.93 | H37: =G37/G38-1 -> 0.04778135 | J37: 46024 | K37: 70.9 | L37: =K37/K38-1 -> 0.05836692 | N37: 46024 | O37: 394.88 | P37: =O37/O38-1 -> -0.037652621 | R37: 46024 | S37: 8.02 | T37: =S37/S38-1 -> 0.029525032 | V37: 46024 | W37: 39.39 | X37: =W37/W38-1 -> 0.013377926 | Z37: 46054 | AA37: 6932.3 | AB37: =AA37/AA38-1 -> -0.00096987619
B38: 01-25-2026 | C38: 315 | D38: =C38/C39-1 -> 0.018593371 | F38: 46047 | G38: 155.5 | H38: =G38/G39-1 -> 0.016539191 | J38: 01-25-2026 | K38: 66.99 | L38: =K38/K39-1 -> -0.020614035 | N38: 01-25-2026 | O38: 410.33 | P38: =O38/O39-1 -> -0.0028432564 | R38: 01-25-2026 | S38: 7.79 | T38: =S38/S39-1 -> -0.074821853 | V38: 01-25-2026 | W38: 38.87 | X38: =W38/W39-1 -> -0.04893565 | Z38: 46047 | AA38: 6939.03 | AB38: =AA38/AA39-1 -> 0.0033865415
B39: 01-18-2026 | C39: 309.25 | D39: =C39/C40-1 -> 0.0059200468 | F39: 46040 | G39: 152.97 | H39: =G39/G40-1 -> -0.045488581 | J39: 01-18-2026 | K39: 68.4 | L39: =K39/K40-1 -> 0.0010244402 | N39: 01-18-2026 | O39: 411.5 | P39: =O39/O40-1 -> 0.028030379 | R39: 01-18-2026 | S39: 8.42 | T39: =S39/S40-1 -> 0.012019231 | V39: 01-18-2026 | W39: 40.87 | X39: =W39/W40-1 -> 0.022772773 | Z39: 46040 | AA39: 6915.61 | AB39: =AA39/AA40-1 -> -0.0035158451
B40: 46327 | C40: 307.43 | D40: =C40/C41-1 -> 0.0003579331 | F40: 46033 | G40: 160.26 | H40: =G40/G41-1 -> 0.030478395 | J40: 46327 | K40: 68.33 | L40: =K40/K41-1 -> -0.0097101449 | N40: 46327 | O40: 400.28 | P40: =O40/O41-1 -> -0.011873905 | R40: 46327 | S40: 8.32 | T40: =S40/S41-1 -> -0.038150289 | V40: 46327 | W40: 39.96 | X40: =W40/W41-1 -> -0.0037397158 | Z40: 46033 | AA40: 6940.01 | AB40: =AA40/AA41-1 -> -0.0037710227
B41: 46113 | C41: 307.32 | D41: =C41/C42-1 -> 0.013387852 | F41: 46026 | G41: 155.52 | H41: =G41/G42-1 -> 0.033424148 | J41: 46113 | K41: 69 | L41: =K41/K42-1 -> 0.017549034 | N41: 46113 | O41: 405.09 | P41: =O41/O42-1 -> -0.047474605 | R41: 46113 | S41: 8.65 | T41: =S41/S42-1 -> 0.05875153 | V41: 46113 | W41: 40.11 | X41: =W41/W42-1 -> 0.069885303 | Z41: 46026 | AA41: 6966.28 | AB41: =AA41/AA42-1 -> 0.015719249
B42: 12-28-2025 | C42: 303.26 | D42: =C42/C43-1 -> -0.023883095 | F42: 46019 | G42: 150.49 | H42: =G42/G43-1 -> -0.017945706 | J42: 12-28-2025 | K42: 67.81 | L42: =K42/K43-1 -> -0.02962221 | N42: 12-28-2025 | O42: 425.28 | P42: =O42/O43-1 -> -0.00065795657 | R42: 12-28-2025 | S42: 8.17 | T42: =S42/S43-1 -> -0.021556886 | V42: 12-28-2025 | W42: 37.49 | X42: =W42/W43-1 -> -0.0084633695 | Z42: 46019 | AA42: 6858.47 | AB42: =AA42/AA43-1 -> -0.010313221
B43: 12-21-2025 | C43: 310.68 | D43: =C43/C44-1 -> -0.016337386 | F43: 46012 | G43: 153.24 | H43: =G43/G44-1 -> -0.0033170732 | J43: 12-21-2025 | K43: 69.88 | L43: =K43/K44-1 -> -0.002426838 | N43: 12-21-2025 | O43: 425.56 | P43: =O43/O44-1 -> -0.013788788 | R43: 12-21-2025 | S43: 8.35 | T43: =S43/S44-1 -> -0.0035799523 | V43: 12-21-2025 | W43: 37.81 | X43: =W43/W44-1 -> 0.0045164718 | Z43: 46012 | AA43: 6929.94 | AB43: =AA43/AA44-1 -> 0.013964445
B44: 12-14-2025 | C44: 315.84 | D44: =C44/C45-1 -> -0.0027784794 | F44: 46005 | G44: 153.75 | H44: =G44/G45-1 -> 0.017807494 | J44: 12-14-2025 | K44: 70.05 | L44: =K44/K45-1 -> -0.011570481 | N44: 12-14-2025 | O44: 431.51 | P44: =O44/O45-1 -> -0.00050957775 | R44: 12-14-2025 | S44: 8.38 | T44: =S44/S45-1 -> -0.026713124 | V44: 12-14-2025 | W44: 37.64 | X44: =W44/W45-1 -> 0.041505257 | Z44: 46005 | AA44: 6834.5 | AB44: =AA44/AA45-1 -> 0.0010384611
...

Sheet WACC
B1: McDONALD’S CORPORATION WACC Calculation
B2: (in USD million except per Share Data)
B4: Cost of Equity | F4: Cost of Debt | K4: Weighted Average Cost of Capital (WACC)
B6: CHOOSE Beta Type | C6: 1 | D6: =IF(C6=A30,B30,B31) -> Bottoms Up Beta | F6: CHOOSE Cost of Debt | G6: 2 | K6: Particulars | L6: Weight | M6: Particulars | N6: Cost | O6: Value
B7: 1 for Bottom-up & 2 for Regression Beta | E7: 1 | F7: =K33 -> Cost of debt (using historical wgted avg interest rate) | K7: Debt (%) | L7: =E27 -> 0.022410703 | M7: Cost of debt (%) | N7: =I12 -> 0.0432288 | O7: =N7*L7 -> 0.0009687878
E8: 2 | F8: =K40 -> Cost of debt (using Credit Rating Method) | K8: Equity (%) | L8: =G27 -> 0.9775893 | M8: Cost of equity (%) | N8: =D14 -> 0.065066452 | O8: =N8*L8 -> 0.063608267
B9: Cost of Equity calculation using Capital Asset Pricing Model (CAPM) | E9: 3 | F9: =K50 -> Cost of debt (using Synthetic Rating Method) | K9: WACC | N9: WACC | O9: =O7+O8 -> 0.064577055
B10: Particulars | C10: Notes | D10: Value
B11: Risk-free rate (%) | C11: 10 year Treasury rate | D11: 0.04362 | F11: ACTIVE CHOICE
B12: Beta | C12: =D6 -> Bottoms Up Beta | D12: =CHOOSE(C6,C30,C31) -> 0.42637082 | F12: =IF(G6=E7, F7, IF(G6=E8, F8, F9)) -> Cost of debt (using Credit Rating Method) | I12: =CHOOSE(G6,M37,M47,M56) -> 0.0432288
B13: Equity market risk premium (%) | D13: 0.0503
B14: Cost of Equity Capital (%) | D14: =D11+(D12*D13) -> 0.065066452
B16: Calculation of Bottom-Up Beta
B17: Particulars | C17: Levered beta or Regression Beta or EQUITY Beta | D17: Average Debt | E17: Avg Debt/(Avg Debt + Avg Equity) | F17: Average Equity (Mkt. Cap) | G17: Avg Equity/(Avg Debt + Avg Equity) | H17: Average Debt / Average Equity | I17: Unlevered beta or ASSET Beta (represents Business Risk) | J17: Relevered beta
B18: Yum! Brands | C18: =Beta!D6 -> 0.34717764 | D18: =AVERAGE(C41:C43) -> 12872.333 | E18: =D18/(D18+F18) -> 0.23766619 | F18: =AVERAGE(F41:F43) -> 41289.067 | G18: =F18/(D18+F18) -> 0.76233381 | H18: =D18/F18 -> 0.31176131 | I18: =C18/(1+(1-$I$27)*H18) -> 0.27856858
B19: Restaurant Brands International | C19: =Beta!D7 -> 0.38570636 | D19: =AVERAGE(C46:C48) -> 15762.667 | E19: =D19/(D19+F19) -> 0.33089322 | F19: =AVERAGE(F46:F48) -> 31874.05 | G19: =F19/(D19+F19) -> 0.66910678 | H19: =D19/F19 -> 0.49452977 | I19: =C19/(1+(1-$I$27)*H19) -> 0.2773512
B20: Domino's Pizza | C20: =Beta!D8 -> 0.74374466 | D20: =AVERAGE(C51:C53) -> 5127.0967 | E20: =D20/(D20+F20) -> 0.26963247 | F20: =AVERAGE(F51:F53) -> 13888.034 | G20: =F20/(D20+F20) -> 0.73036753 | H20: =D20/F20 -> 0.36917369 | I20: =C20/(1+(1-$I$27)*H20) -> 0.57581099
B21: Chipotle (CMG) | C21: =Beta!D10 -> 0.93395764 | D21: =AVERAGE(C56:C58) -> 4954.1033 | E21: =D21/(D21+F21) -> 0.07799795 | F21: =AVERAGE(F56:F58) -> 58561.711 | G21: =F21/(D21+F21) -> 0.92200205 | H21: =D21/F21 -> 0.084596287 | I21: =C21/(1+(1-$I$27)*H21) -> 0.87545036
B22: Wendy's | C22: =Beta!D9 -> 0.41934942 | D22: =AVERAGE(C61:C63) -> 4118.06 | E22: =D22/(D22+F22) -> 0.66500728 | F22: =AVERAGE(F61:F63) -> 2074.4436 | G22: =F22/(D22+F22) -> 0.33499272 | H22: =D22/F22 -> 1.9851395 | I22: =C22/(1+(1-$I$27)*H22) -> 0.16328151
H24: Industry Average | I24: =AVERAGE(I18:I22) -> 0.43409253 | J24: =I24/(1+(1-I27)*H27) -> 0.42637082
B26: Target Company | C26: Levered beta | D26: Average Debt | E26: Avg Debt/(Avg Debt + Avg Equity) | F26: Average Equity (Mkt. Cap) | G26: Avg Equity/(Avg Debt + Avg Equity) | H26: Average Debt / Average Equity | I26: Tax Rate
B27: McDonald's | C27: =Beta!D5 -> 0.30143553 | D27: =AVERAGE(C36:C38) -> 4954.1033 | E27: =D27/(D27+F27) -> 0.022410703 | F27: =AVERAGE(F36:F38) -> 216105.6 | G27: =F27/(D27+F27) -> 0.9775893 | H27: =D27/F27 -> 0.022924456 | I27: 0.21
B29: Beta Calculation for Target Company - McDONALD’S CORPORATION
A30: 1 | B30: Bottoms Up Beta | C30: =J24 -> 0.42637082
A31: 2 | B31: Regression Beta | C31: =C27 -> 0.30143553 | K31: Cost of Debt Calculation
B33: Calculation of Capital Structure of Target & Peer Group Companies | K33: Cost of debt (using historical wgted avg interest rate)
C34: Total Debt (in $ million) | D34: Equity | K34: Particulars | L34: Notes | M34: Value
A35: TARGET | B35: McDONALD’S CORPORATION | D35: Share Price (in $) | E35: Shares O/S | F35: M.Cap | G35: Tax Rate | K35: Debt Borrowing Rate (%) | M35: ='Debt Schedule'!H15 -> 0.038329755
B36: 46103 | C36: 5245.88 | D36: =Beta!C30 -> 305.9 | E36: 713.5 | F36: =D36*E36 -> 218259.65 | G36: 0.21 | K36: Income Tax Rate (%) | M36: =G36 -> 0.21
B37: 46019 | C37: 5075.81 | D37: =Beta!C42 -> 303.26 | E37: 716.4 | F37: =D37*E37 -> 217255.46 | G37: 0.21 | K37: After-tax Cost of Debt (%) | M37: =M35*(1-M36) -> 0.030280506
B38: 45655 | C38: 4540.62 | D38: =Beta!C94 -> 294.78 | E38: 721.9 | F38: =D38*E38 -> 212801.68 | G38: 0.21
A40: PEER 1 | B40: Yum! Brands | K40: Cost of debt (using Credit Rating Method)
B41: 46112 | C41: 13144 | D41: =Beta!G29 -> 156.09 | E41: 279 | F41: =D41*E41 -> 43549.11 | G41: 0.21 | H41: Diluted Weighted Average Shares Outstanding | K41: Particulars | L41: Notes | M41: Value
B42: 46022 | C42: 13187 | D42: =Beta!G42 -> 150.49 | E42: 281 | F42: =D42*E42 -> 42287.69 | G42: 0.21 | K42: Riskfree Rate | M42: =D11 -> 0.04362
B43: 45657 | C43: 12286 | D43: =Beta!G94 -> 133.44 | E43: 285 | F43: =D43*E43 -> 38030.4 | G43: 0.21 | K43: Credit Rating | L43: S&P | M43: BBB
K44: Credit Spread | L44: Prof. Damodaran | M44: 0.0111
A45: PEER 2 | B45: Restaurant Brands International | K45: Debt Borrowing Rate (%) | M45: =M42+M44 -> 0.05472
B46: 46112 | C46: 15683 | D46: =Beta!K29 -> 76.58 | E46: 459 | F46: =D46*E46 -> 35150.22 | G46: 0.21 | K46: Income Tax Rate (%) | M46: =G36 -> 0.21
B47: 46022 | C47: 15679 | D47: =Beta!K42 -> 67.81 | E47: 457 | F47: =D47*E47 -> 30989.17 | G47: 0.21 | K47: After-tax Cost of Debt (%) | M47: =M45*(1-M46) -> 0.0432288
B48: 45657 | C48: 15926 | D48: =Beta!K94 -> 64.94 | E48: 454 | F48: =D48*E48 -> 29482.76 | G48: 0.21
...

Sheet DCF
B1: DCF Calculation
B2: (in USD million except per Share Data)
B3: Valuation Date | C3: 46203
B4: Latest Filing | C4: 46112 | K4: 1 | L4: End-Year Discounting
B5: Choose Discounting (1 for End Year, 2 for Mid-Year) | C5: 1 | K5: 2 | L5: Mid-year Discounting
B6: WACC | C6: =WACC!O9 -> 0.064577055
B7: Tax Rate | C7: =WACC!I27 -> 0.21
